Workbook

Sheet july
B1: NARO WIDE STAFF LIST -AUG .31.2026
B2: POSITION | C2: SALARY SCALE | D2: EMPLOYEE NAME | E2: NIN | F2: GENDER | G2: DATE OF BIRTH | H2: POSTING_STATION | I2: POSTING_TERMS | J2: SUB_GROUP | K2: FIRST APPT DATE | L2: CURRENT APPT_DATE | M2: DATE OF CURRENT CONTRACT | N2: EXPIRY OF CURRENT CONTRACT
B3: NARO SECRETARIAT
B4: OFFICE OF THE DIRECTOR GENERAL
A5: 1 | B5: Director General | C5: UR 1(i) | D5: YONA K. BAGUMA | E5: CM64006107A3TF | F5: Male | G5: 23742 | H5: NAROSEC | I5: CONTRACT | J5: Management | K5: 34335 | L5: 45047 | M5: 45047 | N5: 46873
A6: 2 | B6: Principal Administrative Assistant G.I | C6: UR 3Admin | D6: SYLIVIA LILIAN NAKAZIBWE | E6: CF7303610AZKNC | F6: Female | G6: 26928 | H6: NAROSEC | I6: CONTRACT | J6: Administration | K6: 37316 | L6: 45624 | M6: 45474 | N6: 47299
A7: 3 | B7: Administrative Assistant | C7: UR 6Admin | D7: NAKANDI LYDIA MARIA | E7: CF90024104V20F | F7: Female | G7: 33124 | H7: NAROSEC | I7: CONTRACT | J7: Administration | K7: 45754 | L7: 45754 | M7: 45779 | N7: 47603
A8: 4 | B8: Driver | D8: DERRICK KIBUUKA | E8: CM910521082H46 | F8: Male | G8: 33434 | H8: NAROSEC | I8: CONTRACT | J8: Administration | K8: 46237 | L8: 46237 | M8: 46240 | N8: 48065
A9: 5 | B9: Office Attendant | C9: UR 8 | D9: DAVID MUTANDA LYADDA | E9: CM66060100CZHJ | F9: Male | G9: 24241 | H9: NAROSEC | I9: CONTRACT | J9: Support Staff | K9: 34278 | L9: 34278 | M9: 46174 | N9: 46521
A10: 6 | B10: KIBUUKA DERRICK
B11: DIRECTORATE OF CORPORATE SERVICES
A12: =SEQUENCE(1,962) -> #NAME? | B12: Director Corporate Services | C12: UR 2(i) | D12: STEVENS KISAKA | E12: CM80030101YZ7J | F12: Male | G12: 29503 | H12: NAROSEC | I12: CONTRACT | J12: Management | K12: 45139 | L12: 45139 | M12: 45139 | N12: 46964
A13: 8 | B13: Principal Surveyor | C13: UR 3RS | D13: SUMINI NANSUBUGA | E13: CF7905210CD1ML | F13: Female | G13: 29061 | H13: NAROSEC | I13: CONTRACT | J13: Research | K13: 45517 | L13: 45517 | M13: 45568 | N13: 47391
A14: 9 | B14: Principal Legal Officer | C14: UR 3Admin | D14: NAKAWESA VIOLET | E14: CF78052105ZA7E | F14: Female | G14: 28801 | H14: NAROSEC | I14: CONTRACT | J14: Administration | K14: 41579 | L14: 45275 | M14: 45108 | N14: 46934
A15: 10 | B15: Senior Communication Officer | C15: UR 4Admin | D15: FRANK MUGABI | E15: CM79033104377A | F15: Male | G15: 29043 | H15: NAROSEC | I15: CONTRACT | J15: Administration | K15: 45253 | L15: 45253 | M15: 45242 | N15: 47087
A16: 11 | B16: Digital Media Officer | C16: UR 5(i)RS | D16: DICKSON MUYOMBA | E16: CM86052104TJGK | F16: Male | G16: 31642 | H16: NAROSEC | I16: CONTRACT | J16: Administration | K16: 45253 | L16: 45253 | M16: 45242 | N16: 47087
A17: 12 | B17: Principal Civil Engineer | C17: UR 3RS | D17: RICHARD MUKASA MALE | E17: CM7405210D7TAK | F17: Male | G17: 27269 | H17: NAROSEC | I17: CONTRACT | J17: Research | K17: 43647 | L17: 43647 | M17: 45474 | N17: 47299
A18: 13 | B18: Civil Engineer | C18: UR 5(i)RT | D18: CHARLES KIBIRIGE | E18: CM770231023NFE | F18: Male | G18: 28433 | H18: NAROSEC | I18: CONTRACT | J18: Research Support | K18: 38709 | L18: 44044 | M18: 45108 | N18: 46934
A19: 14 | B19: Principal Procurement Officer | C19: UR 3Admin | D19: EVA NAKIGULI | E19: CF75030101Q73A | F19: Female | G19: 27558 | H19: NAROSEC | I19: CONTRACT | J19: Research | K19: 43252 | L19: 43252 | M19: 45108 | N19: 46934
A20: 15 | B20: Senior Procurement Officer | C20: UR 4Admin | D20: SOLOMON WAJJA | E20: CM8605210G8F2J | F20: Male | G20: 31699 | H20: NAROSEC | I20: CONTRACT | J20: Administration | K20: 41031 | L20: 45278 | M20: 45839 | N20: 47664
A21: 16 | B21: Senior Legal Officer | C21: UR 4Admin | D21: Jackline Sarah Mawemuko | E21: CF87099102CE4E | F21: Female | G21: 32017 | H21: NAROSEC | I21: CONTRACT | K21: 46204 | L21: 46204 | M21: 46174 | N21: 48029
A22: 17 | B22: Legal Officer | C22: UR 5(i)Admin | D22: GEORGE KIWANUKA | E22: CM9405210AXL4J | F22: Male | G22: 34406 | H22: NAROSEC | I22: CONTRACT | J22: Administration | K22: 46217 | L22: 46217 | M22: 46237 | N22: 47909
A23: 18 | B23: Senior Information Technology Officer | C23: UR 4RT | D23: SYLVIA NAMUSOKE KIWANUKA | E23: CF820121039CWE | F23: Female | G23: 30045 | H23: NAROSEC | I23: CONTRACT | J23: Administration | K23: 39490 | L23: 42795 | M23: 45108 | N23: 48062
A24: 19 | B24: Information Technology Officer | C24: UR 5(i)RT | D24: ELENEST JINGO | E24: CM90100100H80F | F24: Male | G24: 33164 | H24: NAROSEC | I24: CONTRACT | J24: Administration | K24: 42737 | L24: 42737 | M24: 45108 | N24: 46934
A25: 20 | B25: Information Technology Officer | D25: ROBERT MUTYABA | E25: CM84017103LKJH | F25: Male | G25: 30975 | H25: NAROSEC | I25: CONTRACT | J25: Administration | K25: 40605 | L25: 44774 | M25: 45474 | N25: 47299
A26: 21 | B26: Senior Administrative Officer | C26: UR 4Admin | D26: NUULU NAKAYIZA | E26: CF81068108DFHK | F26: Female | G26: 29869 | H26: NAROSEC | I26: CONTRACT | J26: Administration | K26: 39142 | L26: 45490 | M26: 45474 | N26: 47299
A27: 22 | B27: Senior Administrative Assistant Grade.I | C27: UR 5(i)Admin | D27: JANE KALIITWA | E27: CF84006106083C | F27: Female | G27: 30832 | H27: NAROSEC | I27: CONTRACT | J27: Administration | K27: 43739 | L27: 45392 | M27: 45839 | N27: 47664
A28: 23 | B28: Procurement Officer | C28: UR 5(i)Admin | D28: SANYA GODFREY | E28: CM90042103W9UH | F28: Male | G28: 33227 | H28: NAROSEC | I28: CONTRACT | J28: Administration | K28: 45747 | L28: 45747 | M28: 45748 | N28: 47573
A29: 24 | B29: Administrative Assistant | C29: UR 6Admin | D29: IMMACULATE KAAHWA | E29: CF8700610797XG | F29: Female | G29: 31826 | H29: NAROSEC | I29: CONTRACT | J29: Administration | K29: 45415 | L29: 45415 | M29: 45415 | N29: 47240
A30: 25 | B30: Driver | C30: UR 7 | D30: STUART KYADDONDO | E30: CM74017101MJVJ | F30: Male | G30: 27225 | H30: NAROSEC | I30: CONTRACT | J30: Support Staff | K30: 37215 | L30: 37215 | M30: 45108 | N30: 46934
A31: 26 | B31: Driver | C31: UR 7 | D31: BUSINGYE IBRAHIM GODWINS | E31: CM790061058ALC | F31: Male | G31: 29215 | H31: NAROSEC | I31: CONTRACT | J31: Support Staff | K31: 42370 | L31: 42370 | M31: 45474 | N31: 47299
A32: 27 | B32: Driver | C32: UR 7 | D32: DDUMBA DAVID | E32: CM84023109D83E | F32: Male | G32: 30682 | H32: NAROSEC | I32: CONTRACT | J32: Support Staff | K32: 36889 | L32: 36889 | M32: 45108 | N32: 46934
A33: 28 | B33: Driver | C33: UR 7 | D33: ADRIKO NICHOLAS | E33: CM92002108ADVH | F33: Male | G33: 33660 | H33: NAROSEC | I33: CONTRACT | J33: Support Staff | K33: 45415 | L33: 45415 | M33: 45415 | N33: 47240
A34: 29 | B34: Driver | C34: UR 7 | D34: SUSANNE AYIKORU | E34: CF83053102EAMJ | F34: Female | G34: 30521 | H34: NAROSEC | I34: CONTRACT | J34: Support Staff | K34: 45415 | L34: 45415 | M34: 45415 | N34: 47240
A35: 30 | B35: Driver | C35: UR 7 | D35: HAMUZA KIBERU | E35: CM96024103FG | F35: Male | G35: 35367 | H35: NAROSEC | I35: CONTRACT | J35: Support Staff | K35: 45870 | L35: 45870 | M35: 45870 | N35: 47726
A36: 31 | B36: Driver | C36: UR 7 | D36: ANDREW KATUMBA | E36: CM9901210AGDRA | F36: Male | G36: 36496 | H36: NAROSEC | I36: CONTRACT | J36: Support Staff | K36: 46099 | L36: 46099 | M36: 46121 | N36: 47946
B37: DIRECTORATE RESEARCH COORDINATION
A39: 33 | B39: Deputy Director General | C39: UR 1(ii) | D39: SWIDIQ MUGERWA | E39: CM800121022GZJ | F39: Male | G39: 29283 | H39: NAROSEC | I39: CONTRACT | J39: Management | K39: 40078 | L39: 42309 | M39: 45139 | N39: 46965
A40: 34 | B40: Senior Principal Research Officer | C40: UR 2(ii)RS | D40: GEORGE LUKWAGO | E40: CM61091100HXYF | F40: Male | G40: 22375 | H40: NAROSEC | I40: CONTRACT | J40: Research | K40: 38596 | L40: 44743 | M40: 45108 | N40: 46847
A41: 35 | B41: Senior Principal Grants Officer | C41: UR 2(ii)RS | D41: VICTORIA TIBENDA NAMULAWA | E41: CF74007108D4TK | F41: Female | G41: 27041 | H41: NAROSEC | I41: CONTRACT | J41: Research | K41: 39056 | L41: 44743 | M41: 45078 | N41: 46934
...

Sheet STRUCTURE 
A1: NARO ESTABLISHMENT_NUMBERS JUNE 2026
A2: =[5]Sheet1!B2 -> POSITION TITLE | B2: =[5]Sheet1!C2 -> SALARY SCALE | C2: =[5]Sheet1!D2 -> APP | D2: =[5]Sheet1!E2 -> FILLED | E2: =[5]Sheet1!F2 -> VACANT | F2: =[5]Sheet1!G2 -> OLD SALARY | G2: =[5]Sheet1!H2 -> NEW SALARY | H2: =[5]Sheet1!I2 -> REMARK
A3: =[5]Sheet1!B3 -> Director General | B3: =[5]Sheet1!C3 -> UR 1(i) | C3: =[5]Sheet1!D3 -> 1 | D3: =[5]Sheet1!E3 -> 1 | E3: =(C3-D3) -> 0 | F3: =[5]Sheet1!G3 -> 20000000 | G3: =[5]Sheet1!H3 -> 20000000
A4: =[5]Sheet1!B4 -> Deputy Director General | B4: =[5]Sheet1!C4 -> UR 1(ii) | C4: =[5]Sheet1!D4 -> 2 | D4: =[5]Sheet1!E4 -> 2 | E4: =(C4-D4) -> 0 | F4: =[5]Sheet1!G4 -> 16900000 | G4: =[5]Sheet1!H4 -> 16900000
A5: =[5]Sheet1!B5 -> Director | B5: =[5]Sheet1!C5 -> UR 2(i) | C5: =[5]Sheet1!D5 -> 19 | D5: =[5]Sheet1!E5 -> 19 | E5: =(C5-D5) -> 0 | F5: =[5]Sheet1!G5 -> 14000000 | G5: =[5]Sheet1!H5 -> 14000000
A6: =[5]Sheet1!B6 -> Senior Principal Grants Officer | B6: =[5]Sheet1!C6 -> UR 2(ii)RS | C6: =[5]Sheet1!D6 -> 1 | D6: =[5]Sheet1!E6 -> 1 | E6: =(C6-D6) -> 0 | F6: =[5]Sheet1!G6 -> 10600000 | G6: =[5]Sheet1!H6 -> 10600000
A7: =[5]Sheet1!B7 -> Senior Principal Research Officer | B7: =[5]Sheet1!C7 -> UR 2(ii)RS | C7: 34 | D7: 12 | E7: =(C7-D7) -> 22 | F7: =[5]Sheet1!G7 -> 10600000 | G7: =[5]Sheet1!H7 -> 10600000
A8: =[5]Sheet1!B8 -> Senior Principal Technology Promotion Officer | B8: =[5]Sheet1!C8 -> UR 2(ii)RS | C8: =[5]Sheet1!D8 -> 1 | D8: =[5]Sheet1!E8 -> 0 | E8: =(C8-D8) -> 1 | F8: =[5]Sheet1!G8 -> 10600000 | G8: =[5]Sheet1!H8 -> 10600000
A9: =[5]Sheet1!B9 -> Senior Principal Research Officer-Production& Documentation | B9: =[5]Sheet1!C9 -> UR 2(ii)RS | C9: =[5]Sheet1!D9 -> 1 | D9: =[5]Sheet1!E9 -> 0 | E9: =(C9-D9) -> 1 | F9: =[5]Sheet1!G9 -> 10600000 | G9: =[5]Sheet1!H9 -> 10600000
A10: =[5]Sheet1!B10 -> Senior Principal Research Officer-Air Quality Control | B10: =[5]Sheet1!C10 -> UR 2(ii)RS | C10: =[5]Sheet1!D10 -> 1 | D10: =[5]Sheet1!E10 -> 0 | E10: =(C10-D10) -> 1 | F10: =[5]Sheet1!G10 -> 10600000 | G10: =[5]Sheet1!H10 -> 10600000
A11: =[5]Sheet1!B11 -> Principal Artificial Intelligence Officer | B11: =[5]Sheet1!C11 -> UR 3RS | C11: =[5]Sheet1!D11 -> 1 | D11: =[5]Sheet1!E11 -> 0 | E11: =(C11-D11) -> 1 | F11: =[5]Sheet1!G11 -> 7500000 | G11: =[5]Sheet1!H11 -> 8500000 | H11: =[5]Sheet1!I11 -> New position
A12: =[5]Sheet1!B12 -> Principal Civil Engineer | B12: =[5]Sheet1!C12 -> UR 3RS | C12: =[5]Sheet1!D12 -> 1 | D12: =[5]Sheet1!E12 -> 1 | E12: =(C12-D12) -> 0 | F12: =[5]Sheet1!G12 -> 7500000 | G12: =[5]Sheet1!H12 -> 8500000 | H12: =[5]Sheet1!I12 -> Change in salary
A13: =[5]Sheet1!B13 -> Principal Information Technology Officer | B13: =[5]Sheet1!C13 -> UR 3RS | C13: =[5]Sheet1!D13 -> 1 | D13: =[5]Sheet1!E13 -> 0 | E13: =(C13-D13) -> 1 | F13: =[5]Sheet1!G13 -> 7500000 | G13: =[5]Sheet1!H13 -> 8500000 | H13: =[5]Sheet1!I13 -> Change in salary
A14: =[5]Sheet1!B14 -> Principal Grants Officer | B14: =[5]Sheet1!C14 -> UR 3RS | C14: =[5]Sheet1!D14 -> 1 | D14: =[5]Sheet1!E14 -> 1 | E14: =(C14-D14) -> 0 | F14: =[5]Sheet1!G14 -> 7500000 | G14: =[5]Sheet1!H14 -> 8500000 | H14: =[5]Sheet1!I14 -> Change in salary
A15: =[5]Sheet1!B15 -> Principal Monitoring and Evaluation Officer | B15: =[5]Sheet1!C15 -> UR 3RS | C15: =[5]Sheet1!D15 -> 1 | D15: =[5]Sheet1!E15 -> 1 | E15: =(C15-D15) -> 0 | F15: =[5]Sheet1!G15 -> 7500000 | G15: =[5]Sheet1!H15 -> 8500000 | H15: =[5]Sheet1!I15 -> Change in salary
A16: =[5]Sheet1!B16 -> Principal Planning Officer | B16: =[5]Sheet1!C16 -> UR 3RS | C16: =[5]Sheet1!D16 -> 1 | D16: =[5]Sheet1!E16 -> 1 | E16: =(C16-D16) -> 0 | F16: =[5]Sheet1!G16 -> 7500000 | G16: =[5]Sheet1!H16 -> 8500000 | H16: =[5]Sheet1!I16 -> Change in salary
A17: =[5]Sheet1!B17 -> Principal Quality Assurance and Compliance Officer | B17: =[5]Sheet1!C17 -> UR 3RS | C17: =[5]Sheet1!D17 -> 1 | D17: =[5]Sheet1!E17 -> 0 | E17: =(C17-D17) -> 1 | F17: =[5]Sheet1!G17 -> 7500000 | G17: =[5]Sheet1!H17 -> 8500000 | H17: =[5]Sheet1!I17 -> Change in salary
A18: =[5]Sheet1!B18 -> Principal Research Officer | B18: =[5]Sheet1!C18 -> UR 3RS | C18: =[5]Sheet1!D18 -> 50 | D18: =[5]Sheet1!E18 -> 31 | E18: =(C18-D18) -> 19 | F18: =[5]Sheet1!G18 -> 7500000 | G18: =[5]Sheet1!H18 -> 8500000 | H18: =[5]Sheet1!I18 -> Change in salary
A19: =[5]Sheet1!B19 -> Principal Surveyor | B19: =[5]Sheet1!C19 -> UR 3RS | C19: =[5]Sheet1!D19 -> 1 | D19: =[5]Sheet1!E19 -> 1 | E19: =(C19-D19) -> 0 | F19: =[5]Sheet1!G19 -> 7500000 | G19: =[5]Sheet1!H19 -> 8500000 | H19: =[5]Sheet1!I19 -> changed Salary& nomenclature
A20: =[5]Sheet1!B20 -> Principal Technology Promotion Officer | B20: =[5]Sheet1!C20 -> UR 3RS | C20: =[5]Sheet1!D20 -> 1 | D20: =[5]Sheet1!E20 -> 1 | E20: =(C20-D20) -> 0 | F20: =[5]Sheet1!G20 -> 7500000 | G20: =[5]Sheet1!H20 -> 8500000 | H20: =[5]Sheet1!I20 -> Change in salary
A21: =[5]Sheet1!B21 -> Principal Technology Promotion Officer Transfer | B21: =[5]Sheet1!C21 -> UR 3RS | C21: =[5]Sheet1!D21 -> 1 | D21: =[5]Sheet1!E21 -> 0 | E21: =(C21-D21) -> 1 | F21: =[5]Sheet1!G21 -> 7500000 | G21: =[5]Sheet1!H21 -> 8500000 | H21: =[5]Sheet1!I21 -> New position & changed salary
A22: =[5]Sheet1!B22 -> Principal Research Officer- M&E | B22: =[5]Sheet1!C22 -> UR 3RS | C22: =[5]Sheet1!D22 -> 1 | D22: =[5]Sheet1!E22 -> 0 | E22: =(C22-D22) -> 1 | F22: =[5]Sheet1!G22 -> 7500000 | G22: =[5]Sheet1!H22 -> 8500000 | H22: =[5]Sheet1!I22 -> New position & changed salary
A23: =[5]Sheet1!B23 -> Principal Research Officer-Building Management Systems | B23: =[5]Sheet1!C23 -> UR 3RS | C23: =[5]Sheet1!D23 -> 1 | D23: =[5]Sheet1!E23 -> 0 | E23: =(C23-D23) -> 1 | F23: =[5]Sheet1!G23 -> 7500000 | G23: =[5]Sheet1!H23 -> 8500000 | H23: =[5]Sheet1!I23 -> New position & changed salary
A24: =[5]Sheet1!B24 -> Principal Administrative Assistant G.I | B24: =[5]Sheet1!C24 -> UR 3Admin | C24: =[5]Sheet1!D24 -> 1 | D24: =[5]Sheet1!E24 -> 1 | E24: =(C24-D24) -> 0 | F24: =[5]Sheet1!G24 -> 6600000 | G24: =[5]Sheet1!H24 -> 6600000
A25: =[5]Sheet1!B25 -> Principal Accountant | B25: =[5]Sheet1!C25 -> UR 3Admin | C25: =[5]Sheet1!D25 -> 5 | D25: =[5]Sheet1!E25 -> 5 | E25: =(C25-D25) -> 0 | F25: =[5]Sheet1!G25 -> 6600000 | G25: =[5]Sheet1!H25 -> 6600000
A26: =[5]Sheet1!B26 -> Principal Communication Officer | B26: =[5]Sheet1!C26 -> UR 3Admin | C26: =[5]Sheet1!D26 -> 1 | D26: =[5]Sheet1!E26 -> 0 | E26: =(C26-D26) -> 1 | F26: =[5]Sheet1!G26 -> 6600000 | G26: =[5]Sheet1!H26 -> 6600000 | H26: =[5]Sheet1!I26 -> New position & changed salary
A27: =[5]Sheet1!B27 -> Principal Human Resource Officer | B27: =[5]Sheet1!C27 -> UR 3Admin | C27: =[5]Sheet1!D27 -> 3 | D27: =[5]Sheet1!E27 -> 3 | E27: =(C27-D27) -> 0 | F27: =[5]Sheet1!G27 -> 6600000 | G27: =[5]Sheet1!H27 -> 6600000 | H27: =[5]Sheet1!I27 -> 0
A28: =[5]Sheet1!B28 -> Principal Human Resource & Administrative Officer | B28: =[5]Sheet1!C28 -> UR 3Admin | C28: =[5]Sheet1!D28 -> 3 | D28: =[5]Sheet1!E28 -> 3 | E28: =(C28-D28) -> 0 | F28: =[5]Sheet1!G28 -> 6600000 | G28: =[5]Sheet1!H28 -> 6600000 | H28: =[5]Sheet1!I28 -> Upgraded position
A29: =[5]Sheet1!B29 -> Principal Internal Auditor | B29: =[5]Sheet1!C29 -> UR 3Admin | C29: =[5]Sheet1!D29 -> 4 | D29: =[5]Sheet1!E29 -> 4 | E29: =(C29-D29) -> 0 | F29: =[5]Sheet1!G29 -> 6600000 | G29: =[5]Sheet1!H29 -> 6600000
A30: =[5]Sheet1!B30 -> Principal Legal Officer | B30: =[5]Sheet1!C30 -> UR 3Admin | C30: =[5]Sheet1!D30 -> 1 | D30: =[5]Sheet1!E30 -> 1 | E30: =(C30-D30) -> 0 | F30: =[5]Sheet1!G30 -> 6600000 | G30: =[5]Sheet1!H30 -> 6600000 | H30: =[5]Sheet1!I30 -> changed Salary& nomenclature
A31: =[5]Sheet1!B31 -> Principal Procurement Officer | B31: =[5]Sheet1!C31 -> UR 3Admin | C31: =[5]Sheet1!D31 -> 1 | D31: =[5]Sheet1!E31 -> 1 | E31: =(C31-D31) -> 0 | F31: =[5]Sheet1!G31 -> 6600000 | G31: =[5]Sheet1!H31 -> 6600000
A32: =[5]Sheet1!B32 -> Senior Environmental Social Safe Guard Officer | B32: =[5]Sheet1!C32 -> UR 4RS | C32: =[5]Sheet1!D32 -> 1 | D32: =[5]Sheet1!E32 -> 1 | E32: =(C32-D32) -> 0 | F32: =[5]Sheet1!G32 -> 6500000 | G32: =[5]Sheet1!H32 -> 7500000 | H32: =[5]Sheet1!I32 -> Change in salary
A33: =[5]Sheet1!B33 -> Senior Biometrician | B33: =[5]Sheet1!C33 -> UR 4RS | C33: =[5]Sheet1!D33 -> 1 | D33: =[5]Sheet1!E33 -> 0 | E33: =(C33-D33) -> 1 | F33: =[5]Sheet1!G33 -> 6500000 | G33: =[5]Sheet1!H33 -> 7500000 | H33: =[5]Sheet1!I33 -> Change in salary
A34: =[5]Sheet1!B34 -> Senior Risk Officer | B34: =[5]Sheet1!C34 -> UR 4RS | C34: =[5]Sheet1!D34 -> 1 | D34: =[5]Sheet1!E34 -> 0 | E34: =(C34-D34) -> 1 | F34: =[5]Sheet1!G34 -> 6500000 | G34: =[5]Sheet1!H34 -> 7500000 | H34: =[5]Sheet1!I34 -> Nomenclature changed& upgraded
A35: =[5]Sheet1!B35 -> Senior Accreditation Officer | B35: =[5]Sheet1!C35 -> UR 4RS | C35: =[5]Sheet1!D35 -> 1 | D35: =[5]Sheet1!E35 -> 0 | E35: =(C35-D35) -> 1 | F35: =[5]Sheet1!G35 -> 6500000 | G35: =[5]Sheet1!H35 -> 7500000 | H35: =[5]Sheet1!I35 -> Change in salary
A36: =[5]Sheet1!B36 -> Senior Research Officer- Grants | B36: =[5]Sheet1!C36 -> UR 4RS | C36: =[5]Sheet1!D36 -> 1 | D36: =[5]Sheet1!E36 -> 0 | E36: =(C36-D36) -> 1 | F36: =[5]Sheet1!G36 -> 6500000 | G36: =[5]Sheet1!H36 -> 7500000 | H36: =[5]Sheet1!I36 -> Upgraded position
A37: =[5]Sheet1!B37 -> Senior Outreach Officer | B37: =[5]Sheet1!C37 -> UR 4RS | C37: =[5]Sheet1!D37 -> 1 | D37: =[5]Sheet1!E37 -> 1 | E37: =(C37-D37) -> 0 | F37: =[5]Sheet1!G37 -> 6500000 | G37: =[5]Sheet1!H37 -> 7500000 | H37: =[5]Sheet1!I37 -> Change in salary
A38: =[5]Sheet1!B38 -> Senior Incubation and Commercialization Officer | B38: =[5]Sheet1!C38 -> UR 4RS | C38: =[5]Sheet1!D38 -> 1 | D38: =[5]Sheet1!E38 -> 1 | E38: =(C38-D38) -> 0 | F38: =[5]Sheet1!G38 -> 6500000 | G38: =[5]Sheet1!H38 -> 7500000 | H38: =[5]Sheet1!I38 -> Change in salary
A39: =[5]Sheet1!B39 -> Senior Intellectual Property Management Officer | B39: =[5]Sheet1!C39 -> UR 4RS | C39: =[5]Sheet1!D39 -> 1 | D39: =[5]Sheet1!E39 -> 1 | E39: =(C39-D39) -> 0 | F39: =[5]Sheet1!G39 -> 6500000 | G39: =[5]Sheet1!H39 -> 7500000 | H39: =[5]Sheet1!I39 -> Change in salary
A40: =[5]Sheet1!B40 -> Senior Database Management& Knowledge Mgt Officer | B40: =[5]Sheet1!C40 -> UR 4RS | C40: =[5]Sheet1!D40 -> 1 | D40: =[5]Sheet1!E40 -> 1 | E40: =(C40-D40) -> 0 | F40: =[5]Sheet1!G40 -> 6500000 | G40: =[5]Sheet1!H40 -> 7500000 | H40: =[5]Sheet1!I40 -> Change in salary
...

Sheet EST.PARI
A1: SUMMARY OF STAFF ESTABLISHMENT AGAINST FILLED AS AT 21/6/2026 | G1: aprp
B2: TOTAL APPROVED | C2: CATEGORY | D2: APPROVED | E2: FILLED | F2: TOTAL FILLED | G2: % STAFFING
A3: NAROSEC | B3: 101 | D3: 101 | E3: 84 | F3: 84
A4: NARL | B4: =(D4+D5+D6) -> 114 | C4: Research Scientist | D4: 45 | E4: 36 | F4: =(E4+E5+E6) -> 78
C5: Technician | D5: 33 | E5: 13
C6: Administration-support | D6: 36 | E6: 29
A7: NACRRI | B7: =(D7+D8+D9) -> 115 | C7: Research Scientist | D7: 44 | E7: 36 | F7: =(E7+E8+E9) -> 81
C8: Technician | D8: 39 | E8: 20
C9: Administration | D9: 32 | E9: 25
A10: NACORI | B10: =(D10+D11+D12) -> 56 | C10: Research Scientist | D10: 21 | E10: 20 | F10: =(E10+E11+E12) -> 40
C11: Technician | D11: 16 | E11: 4
C12: Administration | D12: 19 | E12: 16
A13: NAFORRI | B13: =(D13+D14+D15) -> 89 | C13: Research Scientist | D13: 34 | E13: 19 | F13: =(E13+E14+E15) -> 53
C14: Technician | D14: 25 | E14: 14
C15: Administration | D15: 30 | E15: 20
A16: NAFIRRI | B16: =(D16+D17+D18) -> 98 | C16: Research Scientist | D16: 31 | E16: 20 | F16: =(E16+E17+E18) -> 53
C17: Technician | D17: 29 | E17: 10
C18: Administration | D18: 38 | E18: 23
A19: NALIRRI | B19: =(D21+D20+D19) -> 135 | C19: Research Scientist | D19: 51 | E19: 29 | F19: =(E19+E20+E21) -> 58
C20: Technician | D20: 47 | E20: 10
C21: Administration | D21: 37 | E21: 19
A22: NASARRI | B22: =(D22+D23+D24) -> 96 | C22: Research Scientist | D22: 38 | E22: 19 | F22: =(E23+E24+E22) -> 53
C23: Technician | D23: 25 | E23: 13
C24: Administration | D24: 33 | E24: 21
A25: ABIZARDI | B25: =(D25+D26+D27) -> 43 | C25: Research Scientist | D25: 14 | E25: 6 | F25: =(E27+E26+E25) -> 27
C26: Technician | D26: 11 | E26: 7
C27: Administration | D27: 18 | E27: 14
A28: BUGIZARDI | B28: 48 | C28: Research Scientist | D28: 17 | E28: 8 | F28: =(E30+E29+E28) -> 28
C29: Technician | D29: 15 | E29: 7
C30: Administration | D30: 18 | E30: 13
A31: BULINDI ZARDI | B31: 72 | C31: Research Scientist | D31: 26 | E31: 7 | F31: =(E33+E32+E31) -> 32
C32: Technician | D32: 18 | E32: 10
C33: Administration | D33: 27 | E33: 15
A34: MUKONO ZARDI | B34: 45 | C34: Research Scientist | D34: 16 | E34: 8 | F34: =(E36+E35+E34) -> 29
C35: Technician | D35: 11 | E35: 6
C36: Administration | D36: 18 | E36: 15
A37: MBAZARDI | B37: =(D39+D38+D37) -> 50 | C37: Research Scientist | D37: 18 | E37: 9 | F37: =(E39+E38+E37) -> 33
C38: Technician | D38: 14 | E38: 10
C39: Administration | D39: 18 | E39: 14
A40: NABUIN ZARDI | B40: 44 | C40: Research Scientist | D40: 13 | E40: 7 | F40: =(E42+E41+E40) -> 29
...

Sheet traded off posts
C1: CURRENT ESTABLISHMENT AND STAFFING
A2: ANNEX 1:NARO STRUCTURE FOR TRADED OFF POSITIONS
A3: JOB TITLE | B3: SALARY SCALE | C3: APPROVED ESTAB | D3: TRADED OFF | E3: PROPOSED NEW ESTAB | F3: CURRENT MONTHLY SALARY | G3: CURRENT ANNUAL SALARY
A4: NARL
A5: BIODIVERSITY & BIOTECHNOLOGY - BBP PROGRAM
A6: Senior Principal Research Officer | B6: UR 2(ii)RS | C6: 1 | E6: =C6 -> 1 | F6: 10600000 | G6: =(F6*12) -> 127200000
A7: Principal Research Officer | B7: UR 3RS | C7: 3 | E7: =C7 -> 3 | F7: 8500000 | G7: =(F7*12) -> 102000000
A8: Senior Research Officer | B8: UR 4RS | C8: 4 | E8: =C8 -> 4 | F8: 7500000 | G8: =(F8*12) -> 90000000
A9: Research Officer | B9: UR 5(i)RS | C9: 6 | D9: 1 | E9: 5 | F9: 6000000 | G9: =(F9*12) -> 72000000
A10: Senior Principal Technician | B10: UR 4RT | C10: 1 | E10: =C10 -> 1 | F10: 5600000 | G10: =(F10*12) -> 67200000
A11: Senior Technician | B11: UR 5(ii)RT | C11: 3 | E11: =C11 -> 3 | F11: 3600000 | G11: =(F11*12) -> 43200000
A12: Technician | B12: UR 6RT | C12: 3 | E12: =C12 -> 3 | F12: 2600000 | G12: =(F12*12) -> 31200000
A13: Research Assistant | C13: 0 | E13: 1 | F13: 4500000 | G13: =(F13*12) -> 54000000
A14: Sub Total | C14: =SUM(C6:C12) -> 21 | E14: =SUM(E6:E13) -> 21
A16: SOIL ENVIRONMENT AND AGROMETEREOLOGY RESEARCH PROGRAM
A17: Senior Principal Research Officer | B17: UR 2(ii)RS | C17: 1 | E17: =C17 -> 1 | F17: 10600000 | G17: =(F17*12) -> 127200000
A18: Principal Research Officer | B18: UR 3RS | C18: 2 | E18: =C18 -> 2 | F18: 8500000 | G18: =(F18*12) -> 102000000
A19: Senior Research Officer | B19: UR 4RS | C19: 4 | E19: =C19 -> 4 | F19: 7500000 | G19: =(F19*12) -> 90000000
A20: Research Officer | B20: UR 5(i)RS | C20: 4 | D20: 1 | E20: 3 | F20: 6000000 | G20: =(F20*12) -> 72000000
A21: Senior Principal Technician | B21: UR 4Tech | C21: 1 | E21: =C21 -> 1 | F21: 5600000 | G21: =(F21*12) -> 67200000
A22: Senior Technician | B22: UR 5(ii)Tech | C22: 3 | E22: =C22 -> 3 | F22: 3600000 | G22: =(F22*12) -> 43200000
A23: Technician | B23: UR 6Tech | C23: 3 | E23: =C23 -> 3 | F23: 2600000 | G23: =(F23*12) -> 31200000
A24: Farm Manager | B24: UR 5(i)Tech | C24: 1 | E24: =C24 -> 1 | F24: 4500000 | G24: =(F24*12) -> 54000000
A25: =A13 -> Research Assistant | B25: =B13 -> 0 | C25: =C13 -> 0 | D25: =D13 -> 0 | E25: =E13 -> 1 | F25: =F13 -> 4500000 | G25: =G13 -> 54000000
A26: Sub Total | C26: =SUM(C17:C24) -> 19 | E26: =C26 -> 19
A28: FOOD BIOSCIENCES & AGRIBUSINESS-FBA PROGRAMME
A29: Senior Principal Research Officer | B29: UR 2(ii)RS | C29: 1 | E29: =C29 -> 1 | F29: 10600000 | G29: =(F29*12) -> 127200000
A30: Principal Research Officer | B30: UR 3RS | C30: 2 | E30: =C30 -> 2 | F30: 8500000 | G30: =(F30*12) -> 102000000
A31: Senior Research Officer | B31: UR 4RS | C31: 3 | E31: =C31 -> 3 | F31: 7500000 | G31: =(F31*12) -> 90000000
A32: Research Officer | B32: UR 5(i)RS | C32: 4 | E32: =C32 -> 4 | F32: 6000000 | G32: =(F32*12) -> 72000000
A33: Senior Principal Technician | B33: UR 4Tech | C33: 1 | E33: =C33 -> 1 | F33: 5600000 | G33: =(F33*12) -> 67200000
A34: Principal Technician | B34: UR 5(i)Tech | C34: 1 | E34: =C34 -> 1 | F34: 4500000 | G34: =(F34*12) -> 54000000
A35: Senior Technician | B35: UR 5(ii)Tech | C35: 1 | E35: =C35 -> 1 | F35: 3600000 | G35: =(F35*12) -> 43200000
A36: Technician | B36: UR 6Tech | C36: 3 | E36: =C36 -> 3 | F36: 2600000 | G36: =(F36*12) -> 31200000
A37: =A25 -> Research Assistant | B37: =B25 -> 0 | C37: =C25 -> 0 | D37: =D25 -> 0 | E37: =E25 -> 1 | F37: =F25 -> 4500000 | G37: =G25 -> 54000000
A38: Sub Total | C38: =SUM(C29:C36) -> 16 | E38: =SUM(E29:E37) -> 17
A40: BIOSYSTEMS & AGRICULTURAL ENGINEERING RESEARCH PROGRAMME
A41: Senior Principal Research Officer | B41: UR 2(ii)RS | C41: 1 | E41: 1 | F41: 10600000 | G41: =(F41*12) -> 127200000
A42: Principal Research Officer | B42: UR 3RS | C42: 2 | E42: 2 | F42: 8500000 | G42: =(F42*12) -> 102000000
A43: Senior Research Officer | B43: UR 4RS | C43: 3 | E43: 3 | F43: 7500000 | G43: =(F43*12) -> 90000000
...
